<?xml version="1.0" ?>
<!-- =================================================================================== -->
<!-- |    This document was autogenerated by xacro from robots/j2n6s200_standalone.xacro | -->
<!-- |    EDITING THIS FILE BY HAND IS NOT RECOMMENDED                                 | -->
<!-- =================================================================================== -->
<!-- j2n6s200 refers to jaco v2 6DOF non-spherical 2fingers -->
<robot name="j2n6s200" xmlns:body="http://playerstage.sourceforge.net/gazebo/xmlschema/#body" xmlns:controller="http://playerstage.sourceforge.net/gazebo/xmlschema/#controller" xmlns:gazebo="http://playerstage.sourceforge.net/gazebo/xmlschema/#gz" xmlns:geom="http://playerstage.sourceforge.net/gazebo/xmlschema/#geom" xmlns:interface="http://playerstage.sourceforge.net/gazebo/xmlschema/#interface" xmlns:joint="http://playerstage.sourceforge.net/gazebo/xmlschema/#joint" xmlns:model="http://playerstage.sourceforge.net/gazebo/xmlschema/#model" xmlns:physics="http://playerstage.sourceforge.net/gazebo/xmlschema/#physics" xmlns:renderable="http://playerstage.sourceforge.net/gazebo/xmlschema/#renderable" xmlns:rendering="http://playerstage.sourceforge.net/gazebo/xmlschema/#rendering" xmlns:sensor="http://playerstage.sourceforge.net/gazebo/xmlschema/#sensor" xmlns:xi="http://www.w3.org/2001/XInclude">
  <!-- links      		mesh_no
   base           		0
   shoulder       		1
   arm            		2
   forearm        		3
   wrist          		4
   wrist_spherical_1  8
   wrist_spherical_2  9

   hand_2finger   		56
   finger_proximal		57
   finger_distal      58 
-->
  <!-- links      		mesh_no
   base           		0
   shoulder       		1
   arm            		2
   forearm        		3
   wrist          		4
   wrist_spherical_1  8
   wrist_spherical_2  9

   hand_2finger   		56
   finger_proximal		57
   finger_distal      58 
-->
  <link name="world"/>
  <!--xacro:gazebo_config robot_namespace="${prefix}"/-->
  <link name="j2n6s200_link_base">
    <visual>
      <geometry>
        <mesh filename="package://ada_description/meshes/base.dae"/>
      </geometry>
      <material name="carbon_fiber">
        <color rgba="0.792156862745098 0.819607843137255 0.933333333333333 1"/>
      </material>
    </visual>
    <collision>
      <geometry>
        <mesh filename="package://ada_description/meshes/collision_base.dae"/>
      </geometry>
    </collision>
    <inertial>
      <mass value="0.46784"/>
      <origin rpy="0 0 0" xyz="0 0 0.1255"/>
      <inertia ixx="0.000951270861568" ixy="0" ixz="0" iyy="0.000951270861568" iyz="0" izz="0.00037427200000000004"/>
    </inertial>
  </link>
  <joint name="j2n6s200_joint_base" type="fixed">
    <parent link="world"/>
    <child link="j2n6s200_link_base"/>
    <axis xyz="0 0 0"/>
    <limit effort="2000" lower="0" upper="0" velocity="1.0"/>
    <origin rpy="0 0 0" xyz="0 0 0"/>
    <dynamics damping="0.0" friction="0.0"/>
  </joint>
  <link name="j2n6s200_link_1">
    <visual>
      <geometry>
        <mesh filename="package://ada_description/meshes/shoulder.dae"/>
      </geometry>
      <material name="carbon_fiber">
        <color rgba="0.792156862745098 0.819607843137255 0.933333333333333 1"/>
      </material>
    </visual>
    <visual>
      <geometry>
        <mesh filename="package://ada_description/meshes/ring_big.dae"/>
      </geometry>
    </visual>
    <collision>
      <geometry>
        <mesh filename="package://ada_description/meshes/collision_shoulder.dae"/>
      </geometry>
    </collision>
    <inertial>
      <mass value="0.7477"/>
      <origin xyz="0 -0.002 -0.0605"/>
      <inertia ixx="0.0015203172520400004" ixy="0" ixz="0" iyy="0.0015203172520400004" iyz="0" izz="0.00059816"/>
    </inertial>
  </link>
  <joint name="j2n6s200_joint_1" type="continuous">
    <parent link="j2n6s200_link_base"/>
    <child link="j2n6s200_link_1"/>
    <axis xyz="0 0 1"/>
    <limit effort="2000" lower="-6.283185307179586" upper="6.283185307179586" velocity="1.0"/>
    <origin rpy="0 3.141592653589793 0" xyz="0 0 0.15675"/>
    <dynamics damping="0.0" friction="0.0"/>
  </joint>
  <transmission name="j2n6s200_joint_1_trans">
    <type>transmission_interface/SimpleTransmission</type>
    <joint name="j2n6s200_joint_1">
      <hardwareInterface>EffortJointInterface</hardwareInterface>
    </joint>
    <actuator name="j2n6s200_joint_1_actuator">
      <hardwareInterface>EffortJointInterface</hardwareInterface>
      <mechanicalReduction>160</mechanicalReduction>
    </actuator>
  </transmission>
  <link name="j2n6s200_link_2">
    <visual>
      <geometry>
        <mesh filename="package://ada_description/meshes/arm.dae"/>
      </geometry>
      <material name="carbon_fiber">
        <color rgba="0.792156862745098 0.819607843137255 0.933333333333333 1"/>
      </material>
    </visual>
    <visual>
      <geometry>
        <mesh filename="package://ada_description/meshes/ring_big.dae"/>
      </geometry>
    </visual>
    <collision>
      <geometry>
        <mesh filename="package://ada_description/meshes/collision_arm.dae"/>
      </geometry>
    </collision>
    <inertial>
      <mass value="0.99"/>
      <origin xyz="0 -0.2065 -0.01"/>
      <inertia ixx="0.010502207990999999" ixy="0" ixz="0" iyy="0.0007920000000000001" iyz="0" izz="0.010502207990999999"/>
    </inertial>
  </link>
  <joint name="j2n6s200_joint_2" type="revolute">
    <parent link="j2n6s200_link_1"/>
    <child link="j2n6s200_link_2"/>
    <axis xyz="0 0 1"/>
    <limit effort="2000" lower="0.8203047484373349" upper="5.462880558742252" velocity="1.0"/>
    <origin rpy="-1.5707963267948966 0 3.141592653589793" xyz="0 0.0016 -0.11875"/>
    <dynamics damping="0.0" friction="0.0"/>
  </joint>
  <transmission name="j2n6s200_joint_2_trans">
    <type>transmission_interface/SimpleTransmission</type>
    <joint name="j2n6s200_joint_2">
      <hardwareInterface>EffortJointInterface</hardwareInterface>
    </joint>
    <actuator name="j2n6s200_joint_2_actuator">
      <hardwareInterface>EffortJointInterface</hardwareInterface>
      <mechanicalReduction>160</mechanicalReduction>
    </actuator>
  </transmission>
  <link name="j2n6s200_link_3">
    <visual>
      <geometry>
        <mesh filename="package://ada_description/meshes/forearm.dae"/>
      </geometry>
      <material name="carbon_fiber">
        <color rgba="0.792156862745098 0.819607843137255 0.933333333333333 1"/>
      </material>
    </visual>
    <visual>
      <geometry>
        <mesh filename="package://ada_description/meshes/ring_big.dae"/>
      </geometry>
    </visual>
    <collision>
      <geometry>
        <mesh filename="package://ada_description/meshes/collision_forearm.dae"/>
      </geometry>
    </collision>
    <inertial>
      <mass value="0.6763"/>
      <origin xyz="0 0.081 -0.0086"/>
      <inertia ixx="0.0014202243190800001" ixy="0" ixz="0" iyy="0.000304335" iyz="0" izz="0.0014202243190800001"/>
    </inertial>
  </link>
  <joint name="j2n6s200_joint_3" type="revolute">
    <parent link="j2n6s200_link_2"/>
    <child link="j2n6s200_link_3"/>
    <axis xyz="0 0 1"/>
    <limit effort="2000" lower="0.33161255787892263" upper="5.951572749300664" velocity="1.0"/>
    <origin rpy="0 3.141592653589793 0" xyz="0 -0.410 0"/>
    <dynamics damping="0.0" friction="0.0"/>
  </joint>
  <transmission name="j2n6s200_joint_3_trans">
    <type>transmission_interface/SimpleTransmission</type>
    <joint name="j2n6s200_joint_3">
      <hardwareInterface>EffortJointInterface</hardwareInterface>
    </joint>
    <actuator name="j2n6s200_joint_3_actuator">
      <hardwareInterface>EffortJointInterface</hardwareInterface>
      <mechanicalReduction>160</mechanicalReduction>
    </actuator>
  </transmission>
  <link name="j2n6s200_link_4">
    <visual>
      <geometry>
        <mesh filename="package://ada_description/meshes/wrist.dae"/>
      </geometry>
      <material name="carbon_fiber">
        <color rgba="0.792156862745098 0.819607843137255 0.933333333333333 1"/>
      </material>
    </visual>
    <visual>
      <geometry>
        <mesh filename="package://ada_description/meshes/ring_small.dae"/>
      </geometry>
    </visual>
    <collision>
      <geometry>
        <mesh filename="package://ada_description/meshes/collision_wrist.dae"/>
      </geometry>
    </collision>
    <inertial>
      <mass value="0.1785"/>
      <origin xyz="0 -0.037 -0.0642"/>
      <inertia ixx="7.734969059999999e-05" ixy="0" ixz="0" iyy="7.734969059999999e-05" iyz="0" izz="0.0001428"/>
    </inertial>
  </link>
  <joint name="j2n6s200_joint_4" type="continuous">
    <parent link="j2n6s200_link_3"/>
    <child link="j2n6s200_link_4"/>
    <axis xyz="0 0 1"/>
    <limit effort="2000" lower="-6.283185307179586" upper="6.283185307179586" velocity="1.0"/>
    <origin rpy="-1.5707963267948966 0 3.141592653589793" xyz="0 0.2073 -0.0114"/>
    <dynamics damping="0.0" friction="0.0"/>
  </joint>
  <transmission name="j2n6s200_joint_4_trans">
    <type>transmission_interface/SimpleTransmission</type>
    <joint name="j2n6s200_joint_4">
      <hardwareInterface>EffortJointInterface</hardwareInterface>
    </joint>
    <actuator name="j2n6s200_joint_4_actuator">
      <hardwareInterface>EffortJointInterface</hardwareInterface>
      <mechanicalReduction>160</mechanicalReduction>
    </actuator>
  </transmission>
  <link name="j2n6s200_link_5">
    <visual>
      <geometry>
        <mesh filename="package://ada_description/meshes/wrist.dae"/>
      </geometry>
      <material name="carbon_fiber">
        <color rgba="0.792156862745098 0.819607843137255 0.933333333333333 1"/>
      </material>
    </visual>
    <visual>
      <geometry>
        <mesh filename="package://ada_description/meshes/ring_small.dae"/>
      </geometry>
    </visual>
    <collision>
      <geometry>
        <mesh filename="package://ada_description/meshes/collision_wrist.dae"/>
      </geometry>
    </collision>
    <inertial>
      <mass value="0.1785"/>
      <origin xyz="0 -0.037 -0.0642"/>
      <inertia ixx="7.734969059999999e-05" ixy="0" ixz="0" iyy="7.734969059999999e-05" iyz="0" izz="0.0001428"/>
    </inertial>
  </link>
  <joint name="j2n6s200_joint_5" type="continuous">
    <parent link="j2n6s200_link_4"/>
    <child link="j2n6s200_link_5"/>
    <axis xyz="0 0 1"/>
    <limit effort="2000" lower="-6.283185307179586" upper="6.283185307179586" velocity="1.0"/>
    <origin rpy="1.0471975511965976 0 3.141592653589793" xyz="0 -0.03703 -0.06414"/>
    <dynamics damping="0.0" friction="0.0"/>
  </joint>
  <transmission name="j2n6s200_joint_5_trans">
    <type>transmission_interface/SimpleTransmission</type>
    <joint name="j2n6s200_joint_5">
      <hardwareInterface>EffortJointInterface</hardwareInterface>
    </joint>
    <actuator name="j2n6s200_joint_5_actuator">
      <hardwareInterface>EffortJointInterface</hardwareInterface>
      <mechanicalReduction>160</mechanicalReduction>
    </actuator>
  </transmission>
  <link name="j2n6s200_link_6">
    <visual>
      <geometry>
        <mesh filename="package://ada_description/meshes/hand_2finger.dae"/>
      </geometry>
      <material name="carbon_fiber">
        <color rgba="0.792156862745098 0.819607843137255 0.933333333333333 1"/>
      </material>
    </visual>
    <collision>
      <geometry>
        <mesh filename="package://ada_description/meshes/collision_hand_2finger.dae"/>
      </geometry>
    </collision>
    <inertial>
      <mass value="0.78"/>
      <origin xyz="0 0 -0.06"/>
      <inertia ixx="0.00037049851799999997" ixy="0" ixz="0" iyy="0.00037049851799999997" iyz="0" izz="0.0006240000000000001"/>
    </inertial>
  </link>
  <joint name="j2n6s200_joint_6" type="continuous">
    <parent link="j2n6s200_link_5"/>
    <child link="j2n6s200_link_6"/>
    <axis xyz="0 0 1"/>
    <limit effort="2000" lower="-6.283185307179586" upper="6.283185307179586" velocity="1.0"/>
    <origin rpy="1.0471975511965976 0 3.141592653589793" xyz="0 -0.03703 -0.06414"/>
    <dynamics damping="0.0" friction="0.0"/>
  </joint>
  <transmission name="j2n6s200_joint_6_trans">
    <type>transmission_interface/SimpleTransmission</type>
    <joint name="j2n6s200_joint_6">
      <hardwareInterface>EffortJointInterface</hardwareInterface>
    </joint>
    <actuator name="j2n6s200_joint_6_actuator">
      <hardwareInterface>EffortJointInterface</hardwareInterface>
      <mechanicalReduction>160</mechanicalReduction>
    </actuator>
  </transmission>
  <link name="j2n6s200_end_effector">
  </link>
  <joint name="j2n6s200_joint_end_effector" type="fixed">
    <parent link="j2n6s200_link_6"/>
    <child link="j2n6s200_end_effector"/>
    <axis xyz="0 0 0"/>
    <limit effort="2000" lower="0" upper="0" velocity="1"/>
    <origin rpy="3.141592653589793 0 0" xyz="0 0 -0.1600"/>
  </joint>
  <link name="j2n6s200_hand_tip">
  </link>
  <joint name="j2n6s200_joint_hand_tip" type="fixed">
    <parent link="j2n6s200_end_effector"/>
    <child link="j2n6s200_hand_tip"/>
    <axis xyz="0 0 0"/>
    <limit effort="2000" lower="0" upper="0" velocity="1"/>
    <origin rpy="0 0 0" xyz="0 0 0.0370"/>
  </joint>
  <link name="j2n6s200_hand_base">
  </link>
  <joint name="j2n6s200_joint_hand_base" type="fixed">
    <parent link="j2n6s200_link_6"/>
    <child link="j2n6s200_hand_base"/>
    <axis xyz="0 0 0"/>
    <limit effort="2000" lower="0" upper="0" velocity="1"/>
    <origin rpy="0 0 0" xyz="0 0 0"/>
  </joint>
  <link name="j2n6s200_link_finger_1">
    <visual>
      <geometry>
        <mesh filename="package://ada_description/meshes/finger_proximal.dae"/>
      </geometry>
      <material name="carbon_fiber">
        <color rgba="0.792156862745098 0.819607843137255 0.933333333333333 1"/>
      </material>
    </visual>
    <collision>
      <geometry>
        <mesh filename="package://ada_description/meshes/collision_finger_proximal.dae"/>
      </geometry>
    </collision>
    <inertial>
      <mass value="0.01"/>
      <origin xyz="0.022 0 0"/>
      <inertia ixx="7.8999684e-07" ixy="0" ixz="0" iyy="7.8999684e-07" iyz="0" izz="8e-08"/>
    </inertial>
  </link>
  <joint name="j2n6s200_joint_finger_1" type="revolute">
    <parent link="j2n6s200_hand_base"/>
    <child link="j2n6s200_link_finger_1"/>
    <axis xyz="0 0 1"/>
    <origin rpy="-1.570796327 .649262481663582 1.57079632679490" xyz="-0.0025 0.03095 -0.11482"/>
    <limit effort="2000" lower="0" upper="2" velocity="1"/>
  </joint>
  <transmission name="j2n6s200_joint_finger_1_trans">
    <type>transmission_interface/SimpleTransmission</type>
    <joint name="j2n6s200_joint_finger_1">
      <hardwareInterface>EffortJointInterface</hardwareInterface>
    </joint>
    <actuator name="j2n6s200_joint_finger_1_actuator">
      <hardwareInterface>EffortJointInterface</hardwareInterface>
      <mechanicalReduction>1</mechanicalReduction>
    </actuator>
  </transmission>
  <link name="j2n6s200_link_finger_tip_1">
    <visual>
      <geometry>
        <mesh filename="package://ada_description/meshes/finger_distal.dae"/>
      </geometry>
      <material name="carbon_fiber">
        <color rgba="0.792156862745098 0.819607843137255 0.933333333333333 1"/>
      </material>
    </visual>
    <collision>
      <geometry>
        <mesh filename="package://ada_description/meshes/collision_finger_distal.dae"/>
      </geometry>
    </collision>
    <inertial>
      <mass value="0.01"/>
      <origin xyz="0.022 0 0"/>
      <inertia ixx="7.8999684e-07" ixy="0" ixz="0" iyy="7.8999684e-07" iyz="0" izz="8e-08"/>
    </inertial>
  </link>
  <joint name="j2n6s200_joint_finger_tip_1" type="fixed">
    <parent link="j2n6s200_link_finger_1"/>
    <child link="j2n6s200_link_finger_tip_1"/>
    <axis xyz="0 0 1"/>
    <origin rpy="0 0 0" xyz="0.044 -0.003 0"/>
    <limit effort="0" lower="0" upper="2" velocity="1"/>
  </joint>
  <link name="j2n6s200_link_finger_2">
    <visual>
      <geometry>
        <mesh filename="package://ada_description/meshes/finger_proximal.dae"/>
      </geometry>
      <material name="carbon_fiber">
        <color rgba="0.792156862745098 0.819607843137255 0.933333333333333 1"/>
      </material>
    </visual>
    <collision>
      <geometry>
        <mesh filename="package://ada_description/meshes/collision_finger_proximal.dae"/>
      </geometry>
    </collision>
    <inertial>
      <mass value="0.01"/>
      <origin xyz="0.022 0 0"/>
      <inertia ixx="7.8999684e-07" ixy="0" ixz="0" iyy="7.8999684e-07" iyz="0" izz="8e-08"/>
    </inertial>
  </link>
  <joint name="j2n6s200_joint_finger_2" type="revolute">
    <parent link="j2n6s200_hand_base"/>
    <child link="j2n6s200_link_finger_2"/>
    <axis xyz="0 0 1"/>
    <origin rpy="-1.570796327 .649262481663582 -1.57079632679490" xyz="-0.0025 -0.03095 -0.11482"/>
    <limit effort="2000" lower="0" upper="2" velocity="1"/>
  </joint>
  <transmission name="j2n6s200_joint_finger_2_trans">
    <type>transmission_interface/SimpleTransmission</type>
    <joint name="j2n6s200_joint_finger_2">
      <hardwareInterface>EffortJointInterface</hardwareInterface>
    </joint>
    <actuator name="j2n6s200_joint_finger_2_actuator">
      <hardwareInterface>EffortJointInterface</hardwareInterface>
      <mechanicalReduction>1</mechanicalReduction>
    </actuator>
  </transmission>
  <link name="j2n6s200_link_finger_tip_2">
    <visual>
      <geometry>
        <mesh filename="package://ada_description/meshes/finger_distal.dae"/>
      </geometry>
      <material name="carbon_fiber">
        <color rgba="0.792156862745098 0.819607843137255 0.933333333333333 1"/>
      </material>
    </visual>
    <collision>
      <geometry>
        <mesh filename="package://ada_description/meshes/collision_finger_distal.dae"/>
      </geometry>
    </collision>
    <inertial>
      <mass value="0.01"/>
      <origin xyz="0.022 0 0"/>
      <inertia ixx="7.8999684e-07" ixy="0" ixz="0" iyy="7.8999684e-07" iyz="0" izz="8e-08"/>
    </inertial>
  </link>
  <joint name="j2n6s200_joint_finger_tip_2" type="fixed">
    <parent link="j2n6s200_link_finger_2"/>
    <child link="j2n6s200_link_finger_tip_2"/>
    <axis xyz="0 0 1"/>
    <origin rpy="0 0 0" xyz="0.044 -0.003 0"/>
    <limit effort="0" lower="0" upper="2" velocity="1"/>
  </joint>
  <!--xacro:j2n6s200  base_parent="${robot_root}" /-->
  <link name="j2n6s200_joule">
    <visual>
      <origin rpy="0 0 0" xyz="-0.014 -0.062 -0.023"/>
      <geometry>
        <mesh filename="package://ada_description/meshes/camera_joule.dae" scale="0.001 0.001 0.001"/>
        <!-- <mesh filename="package://ada_description/meshes/collision_camera_joule.dae" scale="0.001 0.001 0.00098"/> -->
      </geometry>
      <material name="carbon_fiber">
        <color rgba="0.792156862745098 0.819607843137255 0.933333333333333 1"/>
      </material>
    </visual>
    <collision>
      <origin rpy="0 0 0" xyz="-0.008 -0.055 0.01"/>
      <geometry>
        <mesh filename="package://ada_description/meshes/collision_camera_joule.dae" scale="0.0008 0.00076 0.0006"/>
      </geometry>
    </collision>
  </link>
  <joint name="j2n6s200_joule" type="fixed">
    <parent link="j2n6s200_link_6"/>
    <child link="j2n6s200_joule"/>
    <axis xyz="0 0 1"/>
    <limit effort="2000" lower="-6.28318530718" upper="6.28318530718" velocity="1"/>
    <origin rpy="1.57079632679 1.57079632679 0" xyz="0.06 0.051 0.0140"/>
    <dynamics damping="0.0" friction="0.0"/>
  </joint>
  <link name="j2n6s200_forque">
    <visual>
      <geometry>
        <mesh filename="package://ada_description/meshes/forque_kinova.dae" scale="0.001 0.001 0.001"/>
      </geometry>
      <material name="carbon_fiber">
        <color rgba="0.792156862745098 0.819607843137255 0.933333333333333 1"/>
      </material>
    </visual>
    <collision>
      <geometry>
        <mesh filename="package://ada_description/meshes/collision_forque_kinova.dae" scale="0.001 0.001 0.001"/>
      </geometry>
    </collision>
  </link>
  <joint name="j2n6s200_joint_forque" type="fixed">
    <parent link="j2n6s200_end_effector"/>
    <child link="j2n6s200_forque"/>
    <axis xyz="0 0 1"/>
    <origin rpy="3.14 0 0" xyz="-0.003 -0.0013 0.065"/>
    <limit effort="2000" lower="0" upper="2" velocity="1"/>
  </joint>
  <link name="j2n6s200_forque_end_effector">
  </link>
  <joint name="j2n6s200_joint_forque_end_effector" type="fixed">
    <parent link="j2n6s200_forque"/>
    <child link="j2n6s200_forque_end_effector"/>
    <axis xyz="0 0 0"/>
    <limit effort="2000" lower="0" upper="0" velocity="1"/>
    <origin rpy="3.1415 0 1.57075" xyz="0.007 0 -0.093"/>
  </joint>
  <link name="j2n6s200_forque_tip">
  </link>
  <joint name="j2n6s200_joint_forque_tip" type="fixed">
    <parent link="j2n6s200_forque"/>
    <child link="j2n6s200_forque_tip"/>
    <axis xyz="0 0 0"/>
    <limit effort="2000" lower="0" upper="0" velocity="1"/>
    <!-- Rotation consistent with pointers of forque: -->
    <origin rpy="2.6415 0 1.57075" xyz="0.007 0 -0.093"/>
  </joint>
</robot>
